#############################################################

                        开始历史爬虫:

#############################################################
--- Logging error ---
Traceback (most recent call last):
  File "/usr/local/python3/lib/python3.8/logging/__init__.py", line 1085, in emit
    self.flush()
  File "/usr/local/python3/lib/python3.8/logging/__init__.py", line 1065, in flush
    self.stream.flush()
OSError: [Errno 28] No space left on device
Call stack:
  File "/usr/local/python3/lib/python3.8/threading.py", line 890, in _bootstrap
    self._bootstrap_inner()
  File "/usr/local/python3/lib/python3.8/threading.py", line 932, in _bootstrap_inner
    self.run()
  File "/usr/local/python3/lib/python3.8/threading.py", line 870, in run
    self._target(*self._args, **self._kwargs)
  File "/usr/local/python3/lib/python3.8/multiprocessing/pool.py", line 513, in _handle_workers
    cls._maintain_pool(ctx, Process, processes, pool, inqueue,
  File "/usr/local/python3/lib/python3.8/multiprocessing/pool.py", line 337, in _maintain_pool
    Pool._repopulate_pool_static(ctx, Process, processes, pool,
  File "/usr/local/python3/lib/python3.8/multiprocessing/pool.py", line 326, in _repopulate_pool_static
    w.start()
  File "/usr/local/python3/lib/python3.8/multiprocessing/process.py", line 121, in start
    self._popen = self._Popen(self)
  File "/usr/local/python3/lib/python3.8/multiprocessing/context.py", line 276, in _Popen
    return Popen(process_obj)
  File "/usr/local/python3/lib/python3.8/multiprocessing/popen_fork.py", line 19, in __init__
    self._launch(process_obj)
  File "/usr/local/python3/lib/python3.8/multiprocessing/popen_fork.py", line 75, in _launch
    code = process_obj._bootstrap(parent_sentinel=child_r)
  File "/usr/local/python3/lib/python3.8/multiprocessing/process.py", line 315, in _bootstrap
    self.run()
  File "/usr/local/python3/lib/python3.8/multiprocessing/process.py", line 108, in run
    self._target(*self._args, **self._kwargs)
  File "/usr/local/python3/lib/python3.8/multiprocessing/pool.py", line 125, in worker
    result = (True, func(*args, **kwds))
  File "/home/ideaman_crawler/arxiv.py", line 257, in crawler_tmp_day
    html = get_one_page(get_url(query_start_date, query_end_date, query_size, query_start))
  File "/home/ideaman_crawler/arxiv.py", line 77, in get_one_page
    response = r.get(url, headers=get_header(), proxies=get_ip())
  File "/usr/local/python3/lib/python3.8/site-packages/requests/api.py", line 76, in get
    return request('get', url, params=params, **kwargs)
  File "/usr/local/python3/lib/python3.8/site-packages/requests/api.py", line 61, in request
    return session.request(method=method, url=url, **kwargs)
  File "/usr/local/python3/lib/python3.8/site-packages/requests/sessions.py", line 530, in request
    resp = self.send(prep, **send_kwargs)
  File "/usr/local/python3/lib/python3.8/site-packages/requests/sessions.py", line 643, in send
    r = adapter.send(request, **kwargs)
  File "/usr/local/python3/lib/python3.8/site-packages/requests/adapters.py", line 439, in send
    resp = conn.urlopen(
  File "/usr/local/python3/lib/python3.8/site-packages/urllib3/connectionpool.py", line 659, in urlopen
    conn = self._get_conn(timeout=pool_timeout)
  File "/usr/local/python3/lib/python3.8/site-packages/urllib3/connectionpool.py", line 279, in _get_conn
    return conn or self._new_conn()
  File "/usr/local/python3/lib/python3.8/site-packages/urllib3/connectionpool.py", line 939, in _new_conn
    log.debug(
Message: 'Starting new HTTPS connection (%d): %s:%s'
Arguments: (1, 'arxiv.org', 443)
--- Logging error ---
Traceback (most recent call last):
  File "/usr/local/python3/lib/python3.8/logging/__init__.py", line 1085, in emit
    self.flush()
  File "/usr/local/python3/lib/python3.8/logging/__init__.py", line 1065, in flush
    self.stream.flush()
OSError: [Errno 28] No space left on device
Call stack:
  File "/usr/local/python3/lib/python3.8/threading.py", line 890, in _bootstrap
    self._bootstrap_inner()
  File "/usr/local/python3/lib/py